<?xml version="1.0" ?>
<!-- =================================================================================== -->
<!-- |    This document was autogenerated by xacro from /home/marsworks/catkin_ws/src/mars_rover/rover_description/urdf/rover.xacro | -->
<!-- |    EDITING THIS FILE BY HAND IS NOT RECOMMENDED                                 | -->
<!-- =================================================================================== -->
<robot name="rover" xmlns:xacro="http://www.ros.org/wiki/xacro">
  <gazebo>
    <plugin filename="libgazebo_ros_skid_steer_drive.so" name="skid_steer_drive_controller">
      <updateRate>100.0</updateRate>
      <robotNamespace>/</robotNamespace>
      <leftFrontJoint>front_left_wheel_joint</leftFrontJoint>
      <rightFrontJoint>front_right_wheel_joint</rightFrontJoint>
      <leftRearJoint>back_left_wheel_joint</leftRearJoint>
      <rightRearJoint>back_right_wheel_joint</rightRearJoint>
      <wheelSeparation>0.525</wheelSeparation>
      <wheelDiameter>0.42</wheelDiameter>
      <robotBaseFrame>base_link</robotBaseFrame>
      <torque>20</torque>
      <topicName>cmd_vel</topicName>
      <broadcastTF>true</broadcastTF>
    </plugin>
  </gazebo>
  <gazebo reference="camera_link">
    <sensor name="depth_camera" type="depth">
      <update_rate>20</update_rate>
      <camera>
        <horizontal_fov>1.047198</horizontal_fov>
        <image>
          <width>640</width>
          <height>480</height>
          <format>R8G8B8</format>
        </image>
        <clip>
          <near>0.05</near>
          <far>3</far>
        </clip>
      </camera>
      <plugin filename="libgazebo_ros_openni_kinect.so" name="camera_controller">
        <baseline>0.2</baseline>
        <alwaysOn>true</alwaysOn>
        <updateRate>1.0</updateRate>
        <cameraName>camera_ir</cameraName>
        <imageTopicName>/camera/depth/image_raw</imageTopicName>
        <cameraInfoTopicName>/camera/depth/camera_info</cameraInfoTopicName>
        <depthImageTopicName>/camera/depth/image_raw</depthImageTopicName>
        <depthImageInfoTopicName>/camera/depth/camera_info</depthImageInfoTopicName>
        <pointCloudTopicName>/camera/depth/points</pointCloudTopicName>
        <frameName>camera_link</frameName>
        <pointCloudCutoff>0.5</pointCloudCutoff>
        <pointCloudCutoffMax>3.0</pointCloudCutoffMax>
        <distortionK1>0.00000001</distortionK1>
        <distortionK2>0.00000001</distortionK2>
        <distortionK3>0.00000001</distortionK3>
        <distortionT1>0.00000001</distortionT1>
        <distortionT2>0.00000001</distortionT2>
        <CxPrime>0</CxPrime>
        <Cx>0</Cx>
        <Cy>0</Cy>
        <focalLength>0</focalLength>
        <hackBaseline>0</hackBaseline>
      </plugin>
    </sensor>
  </gazebo>
  <!--gazebo> <plugin name="gazebo_ros_control" filename="libgazebo_ros_control.so"> <robotNamespace>/rover</robotNamespace> </plugin> </gazebo-->
  <!--gazebo> <plugin name="ground_truth" filename="libgazebo_ros_p3d.so"> <frameName>map</frameName> <bodyName>chassis</bodyName> <topicName>odom</topicName> <updateRate>30.0</updateRate> </plugin> </gazebo-->
  <!--gazebo reference="chassis"> <material>Gazebo/Orange</material> </gazebo-->
  <material name="black">
    <color rgba="0.0 0.0 0.0 1.0"/>
  </material>
  <material name="blue">
    <color rgba="0.0 0.0 0.8 1.0"/>
  </material>
  <material name="green">
    <color rgba="0.0 0.8 0.0 1.0"/>
  </material>
  <material name="grey">
    <color rgba="0.2 0.2 0.2 1.0"/>
  </material>
  <material name="orange">
    <color rgba="1.0 0.423529411765 0.0392156862745 1.0"/>
  </material>
  <material name="brown">
    <color rgba="0.870588235294 0.811764705882 0.764705882353 1.0"/>
  </material>
  <material name="red">
    <color rgba="0.8 0.0 0.0 1.0"/>
  </material>
  <material name="white">
    <color rgba="1.0 1.0 1.0 1.0"/>
  </material>
  <!--xacro:include filename="$(find rover_description)/urdf/arm.xacro"/-->
  <link name="base_link">
    <collision>
      <origin rpy="0 0 0" xyz="0 0 0"/>
      <geometry>
        <box size="0.75 0.45 0.3"/>
      </geometry>
    </collision>
    <visual>
      <origin rpy="0 0 0" xyz="0 0 0"/>
      <geometry>
        <box size="0.75 0.45 0.3"/>
      </geometry>
      <material name="green"/>
    </visual>
  <!--  <inertial>
      <origin rpy="0 0 0" xyz="0 0 0"/>
      <mass value="50"/>
      <inertia ixx="1.21875" ixy="0" ixz="0" iyy="2.71875" iyz="0" izz="2.71875"/>
     </inertial> -->
  </link>
  <link name="front_left_wheel">
    <collision>
      <origin rpy="0 1.57079632679 1.57079632679" xyz="0 0 0"/>
      <geometry>
        <cylinder length="0.075" radius="0.21"/>
      </geometry>
    </collision>
    <visual>
      <origin rpy="0 1.57079632679 1.57079632679" xyz="0 0 0"/>
      <geometry>
        <cylinder length="0.075" radius="0.21"/>
      </geometry>
      <material name="black"/>
    </visual>
    <inertial>
      <origin rpy="0 1.57079632679 1.57079632679" xyz="0 0 0"/>
      <mass value="5"/>
      <inertia ixx="0.05746875" ixy="1e-6" ixz="1e-6" iyy="0.05746875" iyz="1e-6" izz="0.11025"/>
    </inertial>
  </link>
  <gazebo reference="front_left_wheel">
    <mu1 value="1.0"/>
    <mu2 value="1.0"/>
    <kp value="10000000.0"/>
    <kd value="1.0"/>
    <fdir1 value="1 0 0"/>
    <material>Gazebo/Black</material>
  </gazebo>
  <joint name="front_left_wheel_joint" type="continuous">
    <parent link="chassis"/>
    <child link="front_left_wheel"/>
    <origin rpy="0 0 0" xyz="0.3 0.2625 0"/>
    <axis rpy="0 0 0" xyz="0 1 0"/>
    <limit effort="100" velocity="100"/>
    <joint_properties damping="0.0" friction="0.0"/>
  </joint>
  <transmission name="front_left_trans">
    <type>transmission_interface/SimpleTransmission</type>
    <joint name="front_left_wheel_hinge"/>
    <actuator name="front_leftMotor">
      <hardwareInterface>EffortJointInterface</hardwareInterface>
      <mechanicalReduction>10</mechanicalReduction>
    </actuator>
  </transmission>
  <link name="front_right_wheel">
    <collision>
      <origin rpy="0 1.57079632679 1.57079632679" xyz="0 0 0"/>
      <geometry>
        <cylinder length="0.075" radius="0.21"/>
      </geometry>
    </collision>
    <visual>
      <origin rpy="0 1.57079632679 1.57079632679" xyz="0 0 0"/>
      <geometry>
        <cylinder length="0.075" radius="0.21"/>
      </geometry>
      <material name="black"/>
    </visual>
    <inertial>
      <origin rpy="0 1.57079632679 1.57079632679" xyz="0 0 0"/>
      <mass value="5"/>
      <inertia ixx="0.05746875" ixy="1e-6" ixz="1e-6" iyy="0.05746875" iyz="1e-6" izz="0.11025"/>
    </inertial>
  </link>
  <gazebo reference="front_right_wheel">
    <mu1 value="1.0"/>
    <mu2 value="1.0"/>
    <kp value="10000000.0"/>
    <kd value="1.0"/>
    <fdir1 value="1 0 0"/>
    <material>Gazebo/Black</material>
  </gazebo>
  <joint name="front_right_wheel_joint" type="continuous">
    <parent link="chassis"/>
    <child link="front_right_wheel"/>
    <origin rpy="0 0 0" xyz="0.3 -0.2625 0"/>
    <axis rpy="0 0 0" xyz="0 1 0"/>
    <limit effort="100" velocity="100"/>
    <joint_properties damping="0.0" friction="0.0"/>
  </joint>
  <transmission name="front_right_trans">
    <type>transmission_interface/SimpleTransmission</type>
    <joint name="front_right_wheel_hinge"/>
    <actuator name="front_rightMotor">
      <hardwareInterface>EffortJointInterface</hardwareInterface>
      <mechanicalReduction>10</mechanicalReduction>
    </actuator>
  </transmission>
  <link name="back_left_wheel">
    <collision>
      <origin rpy="0 1.57079632679 1.57079632679" xyz="0 0 0"/>
      <geometry>
        <cylinder length="0.075" radius="0.21"/>
      </geometry>
    </collision>
    <visual>
      <origin rpy="0 1.57079632679 1.57079632679" xyz="0 0 0"/>
      <geometry>
        <cylinder length="0.075" radius="0.21"/>
      </geometry>
      <material name="black"/>
    </visual>
    <inertial>
      <origin rpy="0 1.57079632679 1.57079632679" xyz="0 0 0"/>
      <mass value="5"/>
      <inertia ixx="0.05746875" ixy="1e-6" ixz="1e-6" iyy="0.05746875" iyz="1e-6" izz="0.11025"/>
    </inertial>
  </link>
  <gazebo reference="back_left_wheel">
    <mu1 value="1.0"/>
    <mu2 value="1.0"/>
    <kp value="10000000.0"/>
    <kd value="1.0"/>
    <fdir1 value="1 0 0"/>
    <material>Gazebo/Black</material>
  </gazebo>
  <joint name="back_left_wheel_joint" type="continuous">
    <parent link="chassis"/>
    <child link="back_left_wheel"/>
    <origin rpy="0 0 0" xyz="-0.3 0.2625 0"/>
    <axis rpy="0 0 0" xyz="0 1 0"/>
    <limit effort="100" velocity="100"/>
    <joint_properties damping="0.0" friction="0.0"/>
  </joint>
  <transmission name="back_left_trans">
    <type>transmission_interface/SimpleTransmission</type>
    <joint name="back_left_wheel_hinge"/>
    <actuator name="back_leftMotor">
      <hardwareInterface>EffortJointInterface</hardwareInterface>
      <mechanicalReduction>10</mechanicalReduction>
    </actuator>
  </transmission>
  <link name="back_right_wheel">
    <collision>
      <origin rpy="0 1.57079632679 1.57079632679" xyz="0 0 0"/>
      <geometry>
        <cylinder length="0.075" radius="0.21"/>
      </geometry>
    </collision>
    <visual>
      <origin rpy="0 1.57079632679 1.57079632679" xyz="0 0 0"/>
      <geometry>
        <cylinder length="0.075" radius="0.21"/>
      </geometry>
      <material name="black"/>
    </visual>
    <inertial>
      <origin rpy="0 1.57079632679 1.57079632679" xyz="0 0 0"/>
      <mass value="5"/>
      <inertia ixx="0.05746875" ixy="1e-6" ixz="1e-6" iyy="0.05746875" iyz="1e-6" izz="0.11025"/>
    </inertial>
  </link>
  <gazebo reference="back_right_wheel">
    <mu1 value="1.0"/>
    <mu2 value="1.0"/>
    <kp value="10000000.0"/>
    <kd value="1.0"/>
    <fdir1 value="1 0 0"/>
    <material>Gazebo/Black</material>
  </gazebo>
  <joint name="back_right_wheel_joint" type="continuous">
    <parent link="chassis"/>
    <child link="back_right_wheel"/>
    <origin rpy="0 0 0" xyz="-0.3 -0.2625 0"/>
    <axis rpy="0 0 0" xyz="0 1 0"/>
    <limit effort="100" velocity="100"/>
    <joint_properties damping="0.0" friction="0.0"/>
  </joint>
  <transmission name="back_right_trans">
    <type>transmission_interface/SimpleTransmission</type>
    <joint name="back_right_wheel_hinge"/>
    <actuator name="back_rightMotor">
      <hardwareInterface>EffortJointInterface</hardwareInterface>
      <mechanicalReduction>10</mechanicalReduction>
    </actuator>
  </transmission>
  <joint name="camera_joint" type="fixed">
    <axis xyz="0 0 0"/>
    <parent link="base_link"/>
    <child link="camera_link"/>
    <origin rpy="0 0 0" xyz="0.375 0 0.15"/>
  </joint>
  <link name="camera_link">
    <collision>
      <origin rpy="0 0 0" xyz="0 0 0.025"/>
      <geometry>
        <box size="0.05 0.1 0.05"/>
      </geometry>
    </collision>
    <visual>
      <origin rpy="0 0 0" xyz="0 0 0.025"/>
      <geometry>
        <box size="0.05 0.1 0.05"/>
      </geometry>
      <material name="blue"/>
    </visual>
    <inertial>
      <mass value="1e-5"/>
      <origin rpy="0 0 0" xyz="0 0 0.025"/>
      <inertia ixx="1e-6" ixy="1e-6" ixz="1e-6" iyy="1e-6" iyz="1e-6" izz="1e-6"/>
    </inertial>
  </link>
  <joint name="arm_base_joint" type="revolute">
    <axis xyz="0 0 1"/>
    <parent link="base_link"/>
    <child link="arm_base_link"/>
    <limit effort="1" lower="-90" upper="90" velocity="2"/>
    <origin rpy="0 0 0" xyz="0 0 0.15"/>
  </joint>
  <link name="arm_base_link">
    <visual>
      <origin rpy="0 0 0" xyz="0 0 0.03175"/>
      <geometry>
        <cylinder length="0.0635" radius="0.12"/>
      </geometry>
    </visual>
    <inertial>
      <mass value="5"/>
      <origin rpy="0 0 0" xyz="0 0 0.03175"/>
      <inertia ixx="0.05746875" ixy="1e-6" ixz="1e-6" iyy="0.05746875" iyz="1e-6" izz="0.11025"/>
    </inertial>
    <collision>
      <origin rpy="0 0 0" xyz="0 0 0.03175"/>
      <geometry>
        <cylinder length="0.0635" radius="0.12"/>
      </geometry>
    </collision>
  </link>
  <joint name="joint_base_side_plate" type="fixed">
    <parent link="arm_base_link"/>
    <child link="side_plate"/>
    <origin rpy="0 0 0" xyz="0 0 0.0635"/>
  </joint>
  <link name="side_plate">
    <inertial>
      <origin rpy="0 0 0" xyz="0 0 0"/>
      <mass value="0.130"/>
      <inertia ixx="1837000" ixy="120300" ixz="279500" iyy="1651000" iyz="620400" izz="34900"/>
    </inertial>
    <visual>
      <origin rpy="0 0 0" xyz="0 0 0.0825"/>
      <geometry>
        <box size="0.25 0.05 0.165"/>
      </geometry>
      <material name="black"/>
    </visual>
    <collision>
      <origin rpy="0 0 0" xyz="0 0 0.0825"/>
      <geometry>
        <box size="0.25 0.05 0.165"/>
      </geometry>
    </collision>
  </link>
  <joint name="side_motor2" type="revolute">
    <parent link="side_plate"/>
    <child link="motor2"/>
    <axis xyz=" 0 1 0"/>
    <origin rpy="0 0 0" xyz="0 0  0.165"/>
    <dynamics damping="0.1"/>
    <limit effort="100.0" lower="-1.571" upper="1.571" velocity="0.5"/>
  </joint>
  <link name="motor2">
    <visual>
      <origin rpy="0 0 0" xyz="0 0 0.18"/>
      <material name="black"/>
      <geometry>
        <cylinder length="0.36" radius="0.08"/>
      </geometry>
    </visual>
    <collision>
      <origin rpy="0 0 0" xyz="0 0 0.18"/>
      <geometry>
        <cylinder length="0.36" radius="0.08"/>
      </geometry>
    </collision>
    <inertial>
      <origin rpy="0 0 0" xyz="0.416 0 0.154"/>
      <mass value="2"/>
      <inertia ixx="1940000" ixy="1e-6" ixz="-1620000" iyy="3217000" iyz="1e-6" izz="1940000"/>
    </inertial>
  </link>
  <joint name="motor2_motor3_joint" type="revolute">
    <parent link="motor2"/>
    <child link="motor3"/>
    <axis xyz=" 0 1 0"/>
    <origin rpy="0 0 0" xyz="0 0 0.36"/>
    <dynamics damping="0.1"/>
    <limit effort="100.0" lower="-1.571" upper="1.571" velocity="0.5"/>
  </joint>
  <link name="motor3">
    <visual>
      <origin rpy="0 0 0" xyz="0 0 0.25"/>
      <material name="black"/>
      <geometry>
        <cylinder length="0.5" radius="0.05"/>
      </geometry>
    </visual>
    <collision>
      <origin rpy="0 0 0" xyz="0 0 0.25"/>
      <geometry>
        <cylinder length="0.5" radius="0.05"/>
      </geometry>
    </collision>
    <inertial>
      <origin rpy="0 0 0" xyz="0.5 0 0.5"/>
      <mass value="1"/>
      <inertia ixx="57630000" ixy="1e-6" ixz="-50390000" iyy="116300000" iyz="1e-6" izz="59050000"/>
    </inertial>
  </link>
  <joint name="motor3_end_effector_joint" type="revolute">
    <parent link="motor3"/>
    <child link="end_effector"/>
    <axis xyz=" 0 1 0"/>
    <origin rpy="0 0 0" xyz="0 0 0.5"/>
    <dynamics damping="0.1"/>
    <limit effort="100.0" lower="-1.571" upper="1.571" velocity="0.5"/>
  </joint>
  <link name="end_effector">
    <inertial>
      <origin rpy="0 0 0" xyz="0 0 1.0945"/>
      <mass value="0.1"/>
      <inertia ixx="13410" ixy="1e-6" ixz="1e-6" iyy="13850" iyz="1e-6" izz="27150"/>
    </inertial>
    <visual>
      <origin rpy="0 0 0" xyz="0 0 0.039"/>
      <geometry>
        <box size="0.005 0.078 0.078"/>
      </geometry>
      <material name="black"/>
    </visual>
    <collision>
      <origin rpy="0 0 0" xyz="0 0 0.039"/>
      <geometry>
        <box size="0.005 0.078 0.078"/>
      </geometry>
    </collision>
  </link>
</robot>
